Workbook

Sheet Resumen
A1: RESUMEN EJECUTIVO
A2: =+Detalle!A1
A4: ESTADO DE LIQUIDEZ | B4: TOTAL A PAGAR (US$) | C4: SALDO DISPONIBLE (US$) | D4: SALDO PROYECTADO (US$ )
A5: =IF(AND(D35<0,OR(D36<0,D37<0)),"SE NECESITA VENDER Y TRANSFERIR DÓLARES",IF(D35<0,"SE NECESITA VENDER DÓLARES",IF(OR(D36<0,D37<0),"SE NECESITA TRANSFERIR DÓLARES","LIQUIDEZ SUFICIENTE"))) | B5: =ROUNDUP(D18/10000,0)*10000 | C5: =+D25 | D5: =+C31
A7: I. PAGOS A REALIZAR — RESUMEN POR BANCO Y TOTAL
A8: Banco | B8: Operación | C8: Moneda | D8: Importe
A9: BCP | B9: Operación 1 - Pago masivo proveedores | C9: S/ | D9: =+Detalle!O9
A10: BCP | B10: Operación 2 - Pago masivo proveedores | C10: US$ | D10: =+Detalle!O15
A11: BCP | B11: Operación 3 - Pagos varios | C11: S/ | D11: =+Detalle!O33
A12: BCP | B12: Operación 4 - Pagos varios | C12: US$ | D12: =+Detalle!O39
A13: BCP | B13: Operación 5 - Pagos servicios | C13: S/ | D13: =+Detalle!O45
A14: Interbank | B14: Operación 6 - Materia Prima Exterior | C14: US$ | D14: =+Detalle!O84+Detalle!O84
A15: BCP | B15: Operación 7 - Materia Prima Nacional | C15: US$ | D15: =+Detalle!O91
A16: TOTAL SOLES (S/) | D16: =+D9+D11+D13
A17: TOTAL DÓLARES (US$) | D17: =+D10+D12+D14
A18: TOTAL CONSOLIDADO (US$) | B18: Tipo de Cambio | C18: 3.5 | D18: =+(D16/C18)+D17
A20: II. SALDOS DISPONIBLES POR BANCO
A21: Banco | B21: Saldo US$ | C21: Saldo S/ | D21: Total equiv. US$
A22: BCP | D22: =+B22+(C22/C18)
A23: BBVA | D23: =+B23+(C23/C18)
A24: IBK | D24: =+B24+(C24/C18)
A25: TOTAL | B25: =+SUM(B22:B24) | C25: =+SUM(C22:C24) | D25: =+B25+(C25/C18)
A27: III. SALDO PROYECTADO (US$)
A28: Saldo disponible actual | C28: =+D25
A29: (+) Ingreso estimado
A30: (-) Pagos programados semana | C30: =+D18
A31: (=) Nuevo saldo proyectado | C31: =+C28+C29-C30
A33: IV. ESTADO DE LIQUIDEZ
A34: Cuenta | B34: Pagos a Realizar | C34: Saldo Disponible Para Pagos | D34: Excedente / (Déficit)
A35: BCP SOLES | B35: =+D16 | C35: =+C22 | D35: =C35-B35
A36: BCP DÓLARES | B36: =+D10+D12 | C36: =+B22 | D36: =C36-B36
A37: INTERBANK DÓLARES | B37: =+D14 | C37: =+B24 | D37: =C37-B37
A39: V. ALERTAS Y ACCIONES REQUERIDAS
A40: Cuenta | B40: Excedente / (Déficit) | C40: Acción | D40: Monto Venta/Transferencia
A41: BCP SOLES | B41: =C35-B35 | C41: =IF(D35<0,"SE NECESITA VENDER DÓLARES","LIQUIDEZ SUFICIENTE") | D41: =IF(D35<0,-D35/C18,0)
A42: BCP DÓLARES | B42: =+D36 | C42: =IF(D36<0,"SE NECESITA TRANSFERIR DÓLARES","LIQUIDEZ SUFICIENTE") | D42: =IF(D36<0,-D36,0)
A43: INTERBANK DÓLARES | B43: =+D37 | C43: =IF(D37<0,"SE NECESITA TRANSFERIR DÓLARES","LIQUIDEZ SUFICIENTE") | D43: =IF(D37<0,-D37,0)

Sheet Detalle
A1: PAGOS PROVEEDORES 06/07/2026
A3: I. DETALLE DE DOCUMENTOS
A5: Operación 1 - Pago masivo proveedores - Soles
A6: PROVEEDOR | B6: TIPO | C6: N° DOCUMENTO | D6: FEC. REGISTRO | E6: FEC.DOC | F6: FEC.VCTO | G6: IMPORTE | H6: PAGADO | I6: SALDO | J6: PLAZO | K6: % DET | L6: DET | M6: % RET | N6: RET | O6: Neto | P6: DETALLE | Q6: N° O/C-O/S | R6: N° Registro | S6: SUSTENTO
J7: =F7-E7 | O7: =I7-L7-N7
J8: =F8-E8 | O8: =I8-L8-N8
A9: TOTAL | O9: =SUM(O7:O8)
A11: Operación 2 - Pago masivo proveedores - Dólares
A12: PROVEEDOR | B12: TIPO | C12: N° DOCUMENTO | D12: FEC. REGISTRO | E12: FEC.DOC | F12: FEC.VCTO | G12: IMPORTE | H12: PAGADO | I12: SALDO | J12: PLAZO | K12: % DET | L12: DET | M12: % RET | N12: RET | O12: Neto | P12: DETALLE | Q12: N° O/C-O/S | R12: N° Registro | S12: SUSTENTO
J13: =F13-E13 | O13: =I13-L13-N13
J14: =F14-E14 | O14: =I14-L14-N14
A15: TOTAL | O15: =SUM(O13:O14)
A17: AGENTES DE ADUANAS SOLES
A18: PROVEEDOR | B18: TIPO | C18: N° DOCUMENTO | D18: FEC. REGISTRO | E18: FEC.DOC | F18: FEC.VCTO | G18: IMPORTE | H18: PAGADO | I18: SALDO | K18: % DET | L18: DET | M18: % RET | N18: RET | P18: AGENTE ADUANERO | Q18: N° O/C-O/S | S18: LINK FACTURA
J19: =F19-E19 | O19: =I19-L19-N19
J20: =F20-E20 | O20: =I20-L20-N20
A21: TOTAL
A23: AGENTES DE ADUANAS DOLARES
A24: PROVEEDOR | B24: TIPO | C24: N° DOCUMENTO | D24: FEC. REGISTRO | E24: FEC.DOC | F24: FEC.VCTO | G24: IMPORTE | H24: PAGADO | I24: SALDO | K24: % DET | L24: DET | M24: % RET | N24: RET | P24: AGENTE ADUANERO | Q24: N° O/C-O/S | S24: LINK FACTURA
J25: =F25-E25 | O25: =I25-L25-N25
J26: =F26-E26 | O26: =I26-L26-N26
A27: TOTAL
A29: Operación 3 - Pagos varios - Soles
A30: PROVEEDOR | B30: TIPO | C30: N° DOCUMENTO | D30: FEC. REGISTRO | E30: FEC.DOC | F30: FEC.VCTO | G30: IMPORTE | H30: PAGADO | I30: SALDO | J30: PLAZO | K30: % DET | L30: DET | M30: % RET | N30: RET | O30: Neto | P30: DETALLE | Q30: N° O/C-O/S | R30: N° Registro | S30: LINK FACTURA
J31: =F31-E31 | O31: =I31-L31-N31
J32: =F32-E32 | O32: =I32-L32-N32
A33: TOTAL | O33: =SUM(O31:O32)
A35: Operación 4 - Pagos varios - Dólares
A36: PROVEEDOR | B36: TIPO | C36: N° DOCUMENTO | D36: FEC. REGISTRO | E36: FEC.DOC | F36: FEC.VCTO | G36: IMPORTE | H36: PAGADO | I36: SALDO | J36: PLAZO | K36: % DET | L36: DET | M36: % RET | N36: RET | O36: Neto | P36: DETALLE | Q36: N° O/C-O/S | R36: N° Registro | S36: LINK FACTURA
J37: =F37-E37 | O37: =I37-L37-N37
J38: =F38-E38 | O38: =I38-L38-N38
A39: TOTAL | O39: =SUM(#REF!)
A41: Operación 5 - Pagos servicios - Soles
A42: PROVEEDOR | B42: TIPO | C42: N° DOCUMENTO | D42: FEC. REGISTRO | E42: FEC.DOC | F42: FEC.VCTO | G42: IMPORTE | H42: PAGADO | I42: SALDO | J42: PLAZO | K42: % DET | L42: DET | M42: % RET | N42: RET | O42: Neto | P42: DETALLE | Q42: N° O/C-O/S | R42: N° Registro | S42: LINK FACTURA
J43: =F43-E43 | O43: =I43-L43-N43
J44: =F44-E44 | O44: =I44-L44-N44
A45: TOTAL | O45: =SUM(O43:P44)
A47: PAGOS AL PERSONAL SOLES
A48: PROVEEDOR | B48: TIPO | C48: N° DOCUMENTO | D48: FEC. REGISTRO | E48: FEC.DOC | F48: FEC.VCTO | G48: IMPORTE | H48: PAGADO | I48: SALDO | K48: % DET | L48: DET | M48: % RET | N48: RET | P48: DETALLE | Q48: N° O/C-O/S | S48: LINK FACTURA
A49: BANCO BCP | J49: =F49-E49 | O49: =I49
...

Sheet Detalle de agentes
A2: PROVEEDOR | B2: TIPO | C2: N° DOCUMENTO | D2: FEC. REGISTRO | E2: FEC.DOC | F2: FEC.VCTO | G2: IMPORTE | H2: PAGADO | I2: SALDO | J2: % DET | K2: DET | L2: % RET | M2: RET | N2: Neto | O2: PRODUCTO | P2: AGENTE ADUANERO | Q2: N° O/C-O/S | S2: LINK FACTURA
N3: =I3-K3-M3
N4: =I4-K4-M4
N5: =I5-K5-M5
N6: =SUM(N3:N5)
N7: =I7-K7-M7
N8: =I8-K8-M8
N9: =I9-K9-M9
N10: =SUM(N7:N9)
N11: =I11-K11-M11
N12: =I12-K12-M12
N13: =I13-K13-M13
N14: =SUM(N11:N13)
N15: =I15-K15-M15
N16: =I16-K16-M16
N17: =I17-K17-M17
N18: =SUM(N15:N17)
N19: =I19-K19-M19
N20: =I20-K20-M20
N21: =I21-K21-M21
N22: =SUM(N19:N21)
N23: =+N6+N10+N14+N18+N22
A25: PROVEEDOR | B25: TIPO | C25: N° DOCUMENTO | D25: FEC. REGISTRO | E25: FEC.DOC | F25: FEC.VCTO | G25: IMPORTE | H25: PAGADO | I25: SALDO | J25: % DET | K25: DET | L25: % RET | M25: RET | N25: Neto | O25: PRODUCTO | P25: AGENTE ADUANERO | Q25: N° O/C-O/S | S25: LINK FACTURA
N26: =I26-K26-M26
N27: =I27-K27-M27
N28: =I28-K28-M28
N29: =I29-K29-M29
N30: =I30-K30-M30
N31: =I31-K31-M31
N32: =I32-K32-M32
N33: =SUM(N26:N32)
N34: =I34-K34-M34 | P34: DOGANA S.A. AGENTES AFIANZADOS DE ADUANAS
N35: =I35-K35-M35
N36: =I36-K36-M36
N37: =I37-K37-M37
N38: =I38-K38-M38
N39: =I39-K39-M39
N40: =I40-K40-M40
N41: =I41-K41-M41
N42: =I42-K42-M42
...
